<?xml version="1.0" encoding="UTF-8"?>
<!-- Generated by org.testng.reporters.JUnitReportReporter -->
<testsuite hostname="DSR" failures="5" tests="25" name="test.UsersTest" time="1549.197" errors="1" timestamp="2025-03-26T01:44:48 IST" skipped="0">
  <testcase classname="test.UsersTest" name="verifyNavigationToAddUserPage" time="10.859"/>
  <testcase classname="test.UsersTest" name="verifyAddUserWithExistingUserName" time="9.686"/>
  <testcase classname="test.UsersTest" name="verifyAddUserWithInvalidPhoneNumber" time="9.730"/>
  <testcase classname="test.UsersTest" name="verifyAddUserFormFieldPlaceholders" time="8.021"/>
  <testcase classname="test.UsersTest" name="verifyCloseAddUserWithoutEnteringDetailsUsingCloseIcon" time="17.551"/>
  <testcase classname="test.UsersTest" name="verifyAddUserWithMismatchedPassword" time="9.682"/>
  <testcase classname="test.UsersTest" name="verifyAddUserWithLongUserName" time="11.044"/>
  <testcase classname="test.UsersTest" name="verifyCloseAddUserUsingCloseButtonWithEnterDeatils" time="18.814"/>
  <testcase classname="test.UsersTest" name="verifyAddUserWithInvalidEmailFormat" time="10.579"/>
  <testcase classname="test.UsersTest" name="verifyAddUserWithEmptySpacesInFields" time="11.343"/>
  <testcase classname="test.UsersTest" name="verifyUsersModuleFooterSection" time="6.684"/>
  <testcase classname="test.UsersTest" name="verifyAddUserWithExistingEmail" time="9.321">
    <failure message="expected [Email is already exists] but found [User name is already exists]" type="java.lang.AssertionError">
      <![CDATA[java.lang.AssertionError: expected [Email is already exists] but found [User name is already exists]
at org.testng.Assert.fail(Assert.java:111)
at org.testng.Assert.failNotEquals(Assert.java:1578)
at org.testng.Assert.assertEqualsImpl(Assert.java:150)
at org.testng.Assert.assertEquals(Assert.java:132)
at org.testng.Assert.assertEquals(Assert.java:656)
at org.testng.Assert.assertEquals(Assert.java:666)
at test.UsersTest.verifyAddUserWithExistingEmail(UsersTest.java:218)
at java.base/jdk.internal.reflect.DirectMethodHandleAccessor.invoke(DirectMethodHandleAccessor.java:103)
at java.base/java.lang.reflect.Method.invoke(Method.java:580)
at org.testng.internal.invokers.MethodInvocationHelper.invokeMethod(MethodInvocationHelper.java:141)
at org.testng.internal.invokers.TestInvoker.invokeMethod(TestInvoker.java:686)
at org.testng.internal.invokers.TestInvoker.invokeTestMethod(TestInvoker.java:230)
at org.testng.internal.invokers.MethodRunner.runInSequence(MethodRunner.java:63)
at org.testng.internal.invokers.TestInvoker$MethodInvocationAgent.invoke(TestInvoker.java:992)
at org.testng.internal.invokers.TestInvoker.invokeTestMethods(TestInvoker.java:203)
at org.testng.internal.invokers.TestMethodWorker.invokeTestMethods(TestMethodWorker.java:154)
at org.testng.internal.invokers.TestMethodWorker.run(TestMethodWorker.java:134)
at java.base/java.util.ArrayList.forEach(ArrayList.java:1596)
at org.testng.TestRunner.privateRun(TestRunner.java:739)
at org.testng.TestRunner.run(TestRunner.java:614)
at org.testng.SuiteRunner.runTest(SuiteRunner.java:421)
at org.testng.SuiteRunner$SuiteWorker.run(SuiteRunner.java:463)
at org.testng.internal.thread.ThreadUtil.lambda$execute$0(ThreadUtil.java:64)
at java.base/java.util.concurrent.FutureTask.run(FutureTask.java:317)
at java.base/java.util.concurrent.ThreadPoolExecutor.runWorker(ThreadPoolExecutor.java:1144)
at java.base/java.util.concurrent.ThreadPoolExecutor$Worker.run(ThreadPoolExecutor.java:642)
at java.base/java.lang.Thread.run(Thread.java:1583)
]]>
    </failure>
  </testcase> <!-- verifyAddUserWithExistingEmail -->
  <testcase classname="test.UsersTest" name="verifyFieldLabelAndAsteriskSymbolForMandatoryFieldsInAddUserPage" time="10.630"/>
  <testcase classname="test.UsersTest" name="verifyDeleteUser" time="447.447"/>
  <testcase classname="test.UsersTest" name="verifyCloseAddUserUsingCloseIconWithEnterDeatils" time="19.581"/>
  <testcase classname="test.UsersTest" name="verifyAddUserWithValidData" time="9.404">
    <failure message="expected [Successfully submitted!] but found [User name is already exists]" type="java.lang.AssertionError">
      <![CDATA[java.lang.AssertionError: expected [Successfully submitted!] but found [User name is already exists]
at org.testng.Assert.fail(Assert.java:111)
at org.testng.Assert.failNotEquals(Assert.java:1578)
at org.testng.Assert.assertEqualsImpl(Assert.java:150)
at org.testng.Assert.assertEquals(Assert.java:132)
at org.testng.Assert.assertEquals(Assert.java:656)
at org.testng.Assert.assertEquals(Assert.java:666)
at test.UsersTest.verifyAddUserWithValidData(UsersTest.java:176)
at java.base/jdk.internal.reflect.DirectMethodHandleAccessor.invoke(DirectMethodHandleAccessor.java:103)
at java.base/java.lang.reflect.Method.invoke(Method.java:580)
at org.testng.internal.invokers.MethodInvocationHelper.invokeMethod(MethodInvocationHelper.java:141)
at org.testng.internal.invokers.TestInvoker.invokeMethod(TestInvoker.java:686)
at org.testng.internal.invokers.TestInvoker.invokeTestMethod(TestInvoker.java:230)
at org.testng.internal.invokers.MethodRunner.runInSequence(MethodRunner.java:63)
at org.testng.internal.invokers.TestInvoker$MethodInvocationAgent.invoke(TestInvoker.java:992)
at org.testng.internal.invokers.TestInvoker.invokeTestMethods(TestInvoker.java:203)
at org.testng.internal.invokers.TestMethodWorker.invokeTestMethods(TestMethodWorker.java:154)
at org.testng.internal.invokers.TestMethodWorker.run(TestMethodWorker.java:134)
at java.base/java.util.ArrayList.forEach(ArrayList.java:1596)
at org.testng.TestRunner.privateRun(TestRunner.java:739)
at org.testng.TestRunner.run(TestRunner.java:614)
at org.testng.SuiteRunner.runTest(SuiteRunner.java:421)
at org.testng.SuiteRunner$SuiteWorker.run(SuiteRunner.java:463)
at org.testng.internal.thread.ThreadUtil.lambda$execute$0(ThreadUtil.java:64)
at java.base/java.util.concurrent.FutureTask.run(FutureTask.java:317)
at java.base/java.util.concurrent.ThreadPoolExecutor.runWorker(ThreadPoolExecutor.java:1144)
at java.base/java.util.concurrent.ThreadPoolExecutor$Worker.run(ThreadPoolExecutor.java:642)
at java.base/java.lang.Thread.run(Thread.java:1583)
]]>
    </failure>
  </testcase> <!-- verifyAddUserWithValidData -->
  <testcase classname="test.UsersTest" name="verifyUsersModuleDetails" time="7.656">
    <failure message="The following asserts failed:
	Users Page URL is mismatched expected [https://vguard-bt-stg.esealcom.com/null] but found [https://vguard-bt-stg.esealcom.com/admin/authorization/users],
	Users Page Heading mismatchd expected [null] but found [User Management]" type="java.lang.AssertionError">
      <![CDATA[java.lang.AssertionError: The following asserts failed:
Users Page URL is mismatched expected [https://vguard-bt-stg.esealcom.com/null] but found [https://vguard-bt-stg.esealcom.com/admin/authorization/users],
Users Page Heading mismatchd expected [null] but found [User Management]
at org.testng.asserts.SoftAssert.assertAll(SoftAssert.java:46)
at org.testng.asserts.SoftAssert.assertAll(SoftAssert.java:30)
at test.UsersTest.verifyUsersModuleDetails(UsersTest.java:69)
at java.base/jdk.internal.reflect.DirectMethodHandleAccessor.invoke(DirectMethodHandleAccessor.java:103)
at java.base/java.lang.reflect.Method.invoke(Method.java:580)
at org.testng.internal.invokers.MethodInvocationHelper.invokeMethod(MethodInvocationHelper.java:141)
at org.testng.internal.invokers.TestInvoker.invokeMethod(TestInvoker.java:686)
at org.testng.internal.invokers.TestInvoker.invokeTestMethod(TestInvoker.java:230)
at org.testng.internal.invokers.MethodRunner.runInSequence(MethodRunner.java:63)
at org.testng.internal.invokers.TestInvoker$MethodInvocationAgent.invoke(TestInvoker.java:992)
at org.testng.internal.invokers.TestInvoker.invokeTestMethods(TestInvoker.java:203)
at org.testng.internal.invokers.TestMethodWorker.invokeTestMethods(TestMethodWorker.java:154)
at org.testng.internal.invokers.TestMethodWorker.run(TestMethodWorker.java:134)
at java.base/java.util.ArrayList.forEach(ArrayList.java:1596)
at org.testng.TestRunner.privateRun(TestRunner.java:739)
at org.testng.TestRunner.run(TestRunner.java:614)
at org.testng.SuiteRunner.runTest(SuiteRunner.java:421)
at org.testng.SuiteRunner$SuiteWorker.run(SuiteRunner.java:463)
at org.testng.internal.thread.ThreadUtil.lambda$execute$0(ThreadUtil.java:64)
at java.base/java.util.concurrent.FutureTask.run(FutureTask.java:317)
at java.base/java.util.concurrent.ThreadPoolExecutor.runWorker(ThreadPoolExecutor.java:1144)
at java.base/java.util.concurrent.ThreadPoolExecutor$Worker.run(ThreadPoolExecutor.java:642)
at java.base/java.lang.Thread.run(Thread.java:1583)
]]>
    </failure>
  </testcase> <!-- verifyUsersModuleDetails -->
  <testcase classname="test.UsersTest" name="verifyCloseAddUserWithoutEnteringDetailsUsingCloseButton" time="19.044"/>
  <testcase classname="test.UsersTest" name="verifyNavigationToUsersModule" time="7.914"/>
  <testcase classname="test.UsersTest" name="verifyMandatoryFieldAlertsInAddUser" time="11.589"/>
  <testcase classname="test.UsersTest" name="verifyMandatoryFieldValidationForUpdatePassword" time="438.185">
    <error message="no such element: Unable to locate element: {&quot;method&quot;:&quot;xpath&quot;,&quot;selector&quot;:&quot;//*[text()=&#039;Save&#039;]&quot;}
  (Session info: chrome=134.0.6998.118)
For documentation on this error, please visit: https://www.selenium.dev/documentation/webdriver/troubleshooting/errors#no-such-element-exception
Build info: version: &#039;4.28.1&#039;, revision: &#039;73f5ad48a2&#039;
System info: os.name: &#039;Windows 11&#039;, os.arch: &#039;amd64&#039;, os.version: &#039;10.0&#039;, java.version: &#039;21.0.2&#039;
Driver info: org.openqa.selenium.chrome.ChromeDriver
Command: [aa0fea0e82573fda7d44a8f125ceea73, findElement {using=xpath, value=//*[text()=&#039;Save&#039;]}]
Capabilities {acceptInsecureCerts: false, browserName: chrome, browserVersion: 134.0.6998.118, chrome: {chromedriverVersion: 134.0.6998.165 (fd886e2cb29..., userDataDir: C:\Users\dusan\AppData\Loca...}, fedcm:accounts: true, goog:chromeOptions: {debuggerAddress: localhost:50461}, networkConnectionEnabled: false, pageLoadStrategy: normal, platformName: windows, proxy: Proxy(), se:cdp: ws://localhost:50461/devtoo..., se:cdpVersion: 134.0.6998.118, setWindowRect: true, strictFileInteractability: false, timeouts: {implicit: 0, pageLoad: 300000, script: 30000}, unhandledPromptBehavior: dismiss and notify, webauthn:extension:credBlob: true, webauthn:extension:largeBlob: true, webauthn:extension:minPinLength: true, webauthn:extension:prf: true, webauthn:virtualAuthenticators: true}
Session ID: aa0fea0e82573fda7d44a8f125ceea73" type="org.openqa.selenium.NoSuchElementException">
      <![CDATA[org.openqa.selenium.NoSuchElementException: no such element: Unable to locate element: {"method":"xpath","selector":"//*[text()='Save']"}
  (Session info: chrome=134.0.6998.118)
For documentation on this error, please visit: https://www.selenium.dev/documentation/webdriver/troubleshooting/errors#no-such-element-exception
Build info: version: '4.28.1', revision: '73f5ad48a2'
System info: os.name: 'Windows 11', os.arch: 'amd64', os.version: '10.0', java.version: '21.0.2'
Driver info: org.openqa.selenium.chrome.ChromeDriver
Command: [aa0fea0e82573fda7d44a8f125ceea73, findElement {using=xpath, value=//*[text()='Save']}]
Capabilities {acceptInsecureCerts: false, browserName: chrome, browserVersion: 134.0.6998.118, chrome: {chromedriverVersion: 134.0.6998.165 (fd886e2cb29..., userDataDir: C:\Users\dusan\AppData\Loca...}, fedcm:accounts: true, goog:chromeOptions: {debuggerAddress: localhost:50461}, networkConnectionEnabled: false, pageLoadStrategy: normal, platformName: windows, proxy: Proxy(), se:cdp: ws://localhost:50461/devtoo..., se:cdpVersion: 134.0.6998.118, setWindowRect: true, strictFileInteractability: false, timeouts: {implicit: 0, pageLoad: 300000, script: 30000}, unhandledPromptBehavior: dismiss and notify, webauthn:extension:credBlob: true, webauthn:extension:largeBlob: true, webauthn:extension:minPinLength: true, webauthn:extension:prf: true, webauthn:virtualAuthenticators: true}
Session ID: aa0fea0e82573fda7d44a8f125ceea73
at java.base/jdk.internal.reflect.DirectConstructorHandleAccessor.newInstance(DirectConstructorHandleAccessor.java:62)
at java.base/java.lang.reflect.Constructor.newInstanceWithCaller(Constructor.java:502)
at java.base/java.lang.reflect.Constructor.newInstance(Constructor.java:486)
at org.openqa.selenium.remote.ErrorCodec.decode(ErrorCodec.java:167)
at org.openqa.selenium.remote.codec.w3c.W3CHttpResponseCodec.decode(W3CHttpResponseCodec.java:138)
at org.openqa.selenium.remote.codec.w3c.W3CHttpResponseCodec.decode(W3CHttpResponseCodec.java:50)
at org.openqa.selenium.remote.HttpCommandExecutor.execute(HttpCommandExecutor.java:215)
at org.openqa.selenium.remote.service.DriverCommandExecutor.invokeExecute(DriverCommandExecutor.java:216)
at org.openqa.selenium.remote.service.DriverCommandExecutor.execute(DriverCommandExecutor.java:174)
at org.openqa.selenium.remote.RemoteWebDriver.execute(RemoteWebDriver.java:545)
at org.openqa.selenium.remote.ElementLocation$ElementFinder$2.findElement(ElementLocation.java:165)
at org.openqa.selenium.remote.ElementLocation.findElement(ElementLocation.java:59)
at org.openqa.selenium.remote.RemoteWebDriver.findElement(RemoteWebDriver.java:368)
at org.openqa.selenium.remote.RemoteWebDriver.findElement(RemoteWebDriver.java:362)
at org.openqa.selenium.support.pagefactory.DefaultElementLocator.findElement(DefaultElementLocator.java:68)
at org.openqa.selenium.support.pagefactory.internal.LocatingElementHandler.invoke(LocatingElementHandler.java:38)
at jdk.proxy2/jdk.proxy2.$Proxy28.isDisplayed(Unknown Source)
at utils.ElementUtilities.isElementDisplayedOnPage(ElementUtilities.java:169)
at utils.ElementUtilities.clickOnElement(ElementUtilities.java:128)
at pages.UsersPage.clickOnSaveButton(UsersPage.java:276)
at test.UsersTest.verifyMandatoryFieldValidationForUpdatePassword(UsersTest.java:408)
at java.base/jdk.internal.reflect.DirectMethodHandleAccessor.invoke(DirectMethodHandleAccessor.java:103)
at java.base/java.lang.reflect.Method.invoke(Method.java:580)
at org.testng.internal.invokers.MethodInvocationHelper.invokeMethod(MethodInvocationHelper.java:141)
at org.testng.internal.invokers.TestInvoker.invokeMethod(TestInvoker.java:686)
at org.testng.internal.invokers.TestInvoker.invokeTestMethod(TestInvoker.java:230)
at org.testng.internal.invokers.MethodRunner.runInSequence(MethodRunner.java:63)
at org.testng.internal.invokers.TestInvoker$MethodInvocationAgent.invoke(TestInvoker.java:992)
at org.testng.internal.invokers.TestInvoker.invokeTestMethods(TestInvoker.java:203)
at org.testng.internal.invokers.TestMethodWorker.invokeTestMethods(TestMethodWorker.java:154)
at org.testng.internal.invokers.TestMethodWorker.run(TestMethodWorker.java:134)
at java.base/java.util.ArrayList.forEach(ArrayList.java:1596)
at org.testng.TestRunner.privateRun(TestRunner.java:739)
at org.testng.TestRunner.run(TestRunner.java:614)
at org.testng.SuiteRunner.runTest(SuiteRunner.java:421)
at org.testng.SuiteRunner$SuiteWorker.run(SuiteRunner.java:463)
at org.testng.internal.thread.ThreadUtil.lambda$execute$0(ThreadUtil.java:64)
at java.base/java.util.concurrent.FutureTask.run(FutureTask.java:317)
at java.base/java.util.concurrent.ThreadPoolExecutor.runWorker(ThreadPoolExecutor.java:1144)
at java.base/java.util.concurrent.ThreadPoolExecutor$Worker.run(ThreadPoolExecutor.java:642)
at java.base/java.lang.Thread.run(Thread.java:1583)
]]>
    </error>
  </testcase> <!-- verifyMandatoryFieldValidationForUpdatePassword -->
  <testcase classname="test.UsersTest" name="verifyAddUserUsingLeadingAndTrailingSpaces" time="10.042">
    <failure message="The following asserts failed:
	expected [atbs] but found [  atbs  ]" type="java.lang.AssertionError">
      <![CDATA[java.lang.AssertionError: The following asserts failed:
expected [atbs] but found [  atbs  ]
at org.testng.asserts.SoftAssert.assertAll(SoftAssert.java:46)
at org.testng.asserts.SoftAssert.assertAll(SoftAssert.java:30)
at test.UsersTest.verifyAddUserUsingLeadingAndTrailingSpaces(UsersTest.java:440)
at java.base/jdk.internal.reflect.DirectMethodHandleAccessor.invoke(DirectMethodHandleAccessor.java:103)
at java.base/java.lang.reflect.Method.invoke(Method.java:580)
at org.testng.internal.invokers.MethodInvocationHelper.invokeMethod(MethodInvocationHelper.java:141)
at org.testng.internal.invokers.TestInvoker.invokeMethod(TestInvoker.java:686)
at org.testng.internal.invokers.TestInvoker.invokeTestMethod(TestInvoker.java:230)
at org.testng.internal.invokers.MethodRunner.runInSequence(MethodRunner.java:63)
at org.testng.internal.invokers.TestInvoker$MethodInvocationAgent.invoke(TestInvoker.java:992)
at org.testng.internal.invokers.TestInvoker.invokeTestMethods(TestInvoker.java:203)
at org.testng.internal.invokers.TestMethodWorker.invokeTestMethods(TestMethodWorker.java:154)
at org.testng.internal.invokers.TestMethodWorker.run(TestMethodWorker.java:134)
at java.base/java.util.ArrayList.forEach(ArrayList.java:1596)
at org.testng.TestRunner.privateRun(TestRunner.java:739)
at org.testng.TestRunner.run(TestRunner.java:614)
at org.testng.SuiteRunner.runTest(SuiteRunner.java:421)
at org.testng.SuiteRunner$SuiteWorker.run(SuiteRunner.java:463)
at org.testng.internal.thread.ThreadUtil.lambda$execute$0(ThreadUtil.java:64)
at java.base/java.util.concurrent.FutureTask.run(FutureTask.java:317)
at java.base/java.util.concurrent.ThreadPoolExecutor.runWorker(ThreadPoolExecutor.java:1144)
at java.base/java.util.concurrent.ThreadPoolExecutor$Worker.run(ThreadPoolExecutor.java:642)
at java.base/java.lang.Thread.run(Thread.java:1583)
]]>
    </failure>
  </testcase> <!-- verifyAddUserUsingLeadingAndTrailingSpaces -->
  <testcase classname="test.UsersTest" name="verifySearchUser" time="8.274"/>
  <testcase classname="test.UsersTest" name="verifySavedUserDetailsInEditWindow" time="18.864">
    <failure message="The following asserts failed:
	expected [atbs] but found [A B Traders],
	expected [dasfd] but found [Plant],
	expected [1234567890] but found [9948021022],
	expected [abc@yomail.com] but found [Kolkota@plant.com],
	expected [userss] but found [100013],
	expected [Plant] but found [null],
	expected [VCPL - Panthnagar] but found [null],
	expected [None] but found [null],
	expected [Testing role] but found [null]" type="java.lang.AssertionError">
      <![CDATA[java.lang.AssertionError: The following asserts failed:
expected [atbs] but found [A B Traders],
expected [dasfd] but found [Plant],
expected [1234567890] but found [9948021022],
expected [abc@yomail.com] but found [Kolkota@plant.com],
expected [userss] but found [100013],
expected [Plant] but found [null],
expected [VCPL - Panthnagar] but found [null],
expected [None] but found [null],
expected [Testing role] but found [null]
at org.testng.asserts.SoftAssert.assertAll(SoftAssert.java:46)
at org.testng.asserts.SoftAssert.assertAll(SoftAssert.java:30)
at test.UsersTest.verifySavedUserDetailsInEditWindow(UsersTest.java:484)
at java.base/jdk.internal.reflect.DirectMethodHandleAccessor.invoke(DirectMethodHandleAccessor.java:103)
at java.base/java.lang.reflect.Method.invoke(Method.java:580)
at org.testng.internal.invokers.MethodInvocationHelper.invokeMethod(MethodInvocationHelper.java:141)
at org.testng.internal.invokers.TestInvoker.invokeMethod(TestInvoker.java:686)
at org.testng.internal.invokers.TestInvoker.invokeTestMethod(TestInvoker.java:230)
at org.testng.internal.invokers.MethodRunner.runInSequence(MethodRunner.java:63)
at org.testng.internal.invokers.TestInvoker$MethodInvocationAgent.invoke(TestInvoker.java:992)
at org.testng.internal.invokers.TestInvoker.invokeTestMethods(TestInvoker.java:203)
at org.testng.internal.invokers.TestMethodWorker.invokeTestMethods(TestMethodWorker.java:154)
at org.testng.internal.invokers.TestMethodWorker.run(TestMethodWorker.java:134)
at java.base/java.util.ArrayList.forEach(ArrayList.java:1596)
at org.testng.TestRunner.privateRun(TestRunner.java:739)
at org.testng.TestRunner.run(TestRunner.java:614)
at org.testng.SuiteRunner.runTest(SuiteRunner.java:421)
at org.testng.SuiteRunner$SuiteWorker.run(SuiteRunner.java:463)
at org.testng.internal.thread.ThreadUtil.lambda$execute$0(ThreadUtil.java:64)
at java.base/java.util.concurrent.FutureTask.run(FutureTask.java:317)
at java.base/java.util.concurrent.ThreadPoolExecutor.runWorker(ThreadPoolExecutor.java:1144)
at java.base/java.util.concurrent.ThreadPoolExecutor$Worker.run(ThreadPoolExecutor.java:642)
at java.base/java.lang.Thread.run(Thread.java:1583)
]]>
    </failure>
  </testcase> <!-- verifySavedUserDetailsInEditWindow -->
  <testcase classname="test.UsersTest" name="verifyUserInUsersModuleGridWithPagination" time="407.253"/>
</testsuite> <!-- test.UsersTest -->
